Workbook

Sheet Spesifikasi Bahan
A1: Kode Bahan | B1: Nama Bahan Kimia | C1: Rumus Kimia | D1: Spesifikasi Teknis/Nomor Katalog | E1: Qty/Pack | F1: Unit/Pack | G1: Min. Qty | H1: Kegunaan Analisa | I1: SDS | J1: COA
A2: A1 | B2: Stearic Acid | C2: C18H36O2 | D2: 1.75366.0100 SigmaAldrich | E2: 500 | F2: gram | G2: 250 | H2: OG | I2: https://drive.google.com/file/d/1DdKRl18J2QwtzrQO4h1eloQyiNbwU6u7/view?usp=sharing | J2: https://drive.google.com/file/d/1j5vRepveXAirePtUJGhK74Wuyr-An6DR/view?usp=drive_link
A3: A2 | B3: 1,8-Dihydroxy-2-(4-Sulfophenylazo)-Naphthalen-3,6-Disulfonic Acid Trisodium Salt/SPADNS | C3: - | D3: 1.07998.0025 - SigmaAldrich | E3: 25 | F3: gram | G3: 10 | H3: F | I3: https://drive.google.com/file/d/1AfE_YWvNev5AogofXvKKQW93Vv6hzL4r/view?usp=drive_link | J3: https://drive.google.com/file/d/1ShXX4IcZruJ3yR0fFBpueCQU8p5lL5Xj/view?usp=drive_link
A4: A3 | B4: N-(1-Naphtyl)ethylenediamine dihydrochloride NEDA | C4: - | D4: 1.06237.0025 - SigmaAldrich | E4: 25 | F4: gram | G4: 10 | H4: NO3, NO2, NO2-UA, | I4: https://drive.google.com/file/d/1ZfN2suCocxuoWple7vDu_Rbon5EIn9rv/view?usp=drive_link | J4: https://drive.google.com/file/d/15fYRttBMYwkTcbDsGTXW3_Y5qNQiUHv0/view?usp=drive_link
A5: A4 | B5: Butir Cadmium | C5: Cd | D5: 1.02001.0250 - SigmaAldrich | E5: 250 | F5: gram | G5: 100 | H5: NO3 | I5: https://drive.google.com/file/d/1dGt-dAh6UeLitst0kRlyq4m298F47PLJ/view?usp=drive_link | J5: https://drive.google.com/file/d/1HzB9_yDC_nk3tX5uFx30Xc8KC-KQcBDI/view?usp=drive_link
A6: A5 | B6: L-Glutamic Acid | C6: C5H9NO4 | D6: 1.00291.0250 - SigmaAldrich | E6: 250 | F6: gram | G6: 100 | H6: BOD | I6: https://drive.google.com/file/d/1ozk6syeIV0Ue0FEXudgvKrE1DQYpwCUP/view?usp=drive_link | J6: https://drive.google.com/file/d/1m54H1jyBNhV8VSlVLzHLZonT7pLjJXJG/view?usp=drive_link
A7: A6 | B7: Starch Soluble | C7: (C₆H₁₀O₅)n | D7: 1.01252.0100 - Merck | E7: 100 | F7: gram | G7: 10 | H7: Fenol, H2S-U, Ox, | I7: https://drive.google.com/file/d/1M5mJwkk6tnvF8TZD9bfSVcTBiEYSMqB9/view?usp=drive_link | J7: https://drive.google.com/file/d/1S49pU0urzJS_Ht2pjFy6Mv7FLHYDc9qV/view?usp=drive_link
A8: A7 | B8: Tembaga(II) Sulfat Pentahidrat | C8: CuSO4.5H2O | D8: A-2002 - Smartlab | E8: 1000 | F8: gram | G8: 250 | H8: NO3, Uji kinerja | I8: https://drive.google.com/file/d/1YfW6PobEyv9uVpt48GYv6PVkd3SndjmF/view?usp=drive_link | J8: https://drive.google.com/file/d/1ikmkfAPtlPsAayyDUlW3Aj4XXRI3tR_w/view?usp=drive_link
A9: A8 | B9: Magnesium Chloride Hexahydrate | C9: MgCl2.6H2O | D9: 1.05833.0250 - Merck | E9: 250 | F9: gram | G9: 100 | H9: OG, CN | I9: https://drive.google.com/open?id=1JyKmR43kNB5dlO_I18z2IaNJNkxddK4_ | J9: https://drive.google.com/file/d/1rD2NG17jQt4oXdgyyyrRgzE3rYXTWJw_/view?usp=drive_link
A10: A9 | B10: Potasium Iodida | C10: KI | D10: A-2039 - Smart - Lab | E10: 500 | F10: gram | G10: 10 | H10: Fenol, H2S-U, Ox, | I10: https://drive.google.com/file/d/1lDNPLLq060jHv1nXsQtN5V1i1V6MIBq3/view?usp=drive_link | J10: https://drive.google.com/file/d/1pI1dqkpT1JL7ja10DkX-DeccrmCMx1vK/view?usp=drive_link
A11: A10 | B11: orto-Asam Fosfor 85% | C11: (COOH)₂.2 H₂O | D11: 05074 - LobaChemie | E11: 500 | F11: gram | G11: 50 | H11: KMnO4 | I11: https://drive.google.com/file/d/1tpnKnk1bCg1gfmLipTvLZGm5LVXPPx5x/view?usp=drive_link | J11: https://drive.google.com/file/d/1MUiO8uXF5m0_CMIO1JGDUDKWKAotu7Ja/view?usp=drive_link
A12: A11 | B12: Potasium Klorida | C12: KCl | D12: 1.04936.0250 - SigmaAldrich | E12: 500 | F12: gram | G12: 10 | H12: DHL,SO2 | I12: https://drive.google.com/file/d/1JWO6qIekSxTqNtbZYxYjuVu17m4rIf1-/view?usp=drive_link | J12: https://drive.google.com/file/d/1Gwc7J4it9Mf-jdOlsg3MHO8KQ6vS4nq_/view?usp=drive_link
A13: A12 | B13: Potasium Iodat | C13: KIO₃ | D13: 215929.0100 SigmaAldrich | E13: 100 | F13: gram | G13: 50 | H13: Ox | I13: https://drive.google.com/file/d/1Xz9d8fXaWwwcl3WuU8wmSu85eRabrWnP/view?usp=drive_link | J13: https://drive.google.com/file/d/1cmGRvcbqll72q9-1_WEBdsDzjcL8ZSzC/view?usp=drive_link
... A18: A17 | B18: Sulfanilic Acid | C18: NH₂C₆H₄SO₃H | D18: 1.00686.0250 - Supelco | E18: 100 | F18: gram | G18: 100 | H18: NO2-UA | I18: https://drive.google.com/file/d/1CUukh3PO4IS56vVlJtlCIDiXxaCUEJ5i/view?usp=drive_link | J18: https://drive.google.com/file/d/1fB_fMurrgsavZYLV8zvGMfl6Xdcw693a/view?usp=drive_link
A19: A18 | B19: Manganese (II) Sulfate Monohydrate | C19: MnSO₄.H₂O | D19: 1.05941.0250 - Supelco | E19: 250 | F19: gram | G19: 100 | I19: https://drive.google.com/file/d/1UrF-mAbO_IFEfRH8lPJNFu0Tj7FlzfpP/view?usp=drive_link | J19: https://drive.google.com/file/d/13f3HrFi9HF4rjj5QRFtW_P1bcAXXDz_t/view?usp=drive_link
A20: A19 | B20: Potasium Hidrogen Ptalat | C20: C₈H₅KO₄ | D20: 1.04874.0250 - Supelco | E20: 250 | F20: gram | G20: 100 | H20: COD | I20: https://drive.google.com/file/d/1EXGvn7KRBd7RqZuEuWgwRAXSfYVJsib7/view?usp=drive_link | J20: https://drive.google.com/file/d/1b-1ZqydFX4zKl_NxJh0Y9HDavD6H6Si0/view?usp=drive_link
A21: A20 | B21: Potasium Nitrat | C21: KNO₃ | D21: 1.05063.0500 - Supelco | E21: 500 | F21: gram | G21: 250 | H21: NO3,PO4 | I21: https://drive.google.com/file/d/1yZApZidjWgcbpKokYMp4hjhtlP-7ns_G/view?usp=drive_link | J21: https://drive.google.com/file/d/1k2fNOLKwqIkm2z8CUj68QWIvGXtZUdGE/view?usp=drive_link
A22: A21 | B22: Di-Sodium Hidrogen Posfat Dodekahidrat | C22: Na₂HPO₄.12H₂O | D22: 1.06579.0500 - Supelco | E22: 500 | F22: gram | G22: 200 | H22: Ox | I22: https://drive.google.com/file/d/1vb1myK04IHP-Ju8sKQ3HFglu5AxW1pBa/view?usp=drive_link | J22: https://drive.google.com/file/d/1N0lYcrVwAM4yar9B-JHF2OQS_RT_1N2f/view?usp=drive_link
A23: A22 | B23: Sodium Hidroksida | C23: NaOH | D23: 1.06498.0500 - Supelco/ 605K6006 - Kanto Chemical | E23: 500 | F23: gram | G23: 250 | H23: NH3-LC, Cl-LC, Cr6+, CN, MBAS, fenol, formaldehide, H2S-U, NH3-UA, HCl, NH3-UE, | I23: https://drive.google.com/file/d/1kPRaamHZXJRJBvLTUCU_yKtyk7tIVjAE/view?usp=drive_link | J23: https://drive.google.com/file/d/1CbAF245YelBlIDhMWO-xXDuQgdKZ-l36/view?usp=drive_link | K23: https://drive.google.com/file/d/1HIAslhCb9wPxUvgG6_758ts0lOuGzS4O/view?usp=drive_link
A24: A23 | B24: Sodium Dihidrogen Posfat Monohidrat | C24: NaH₂PO₄.H₂O | D24: 1.06346.1000 - Supelco | E24: 1000 | F24: gram | G24: 500 | H24: MBAS | I24: https://drive.google.com/file/d/1_2vEHaSNED5GjWsZHA06pCOgxXLekFcs/view?usp=drive_link | J24: https://drive.google.com/file/d/1UK1EDgucGEmqBzRc4ors3ltisTkjZbON/view?usp=drive_link
A25: A24 | B25: Phenol | C25: C₆H₅OH | D25: 1.00206.1000 - Supelco | E25: 250 | F25: gram | G25: 100 | H25: NH3 | I25: https://drive.google.com/file/d/1d5r4SuZoUz_bJC-y006F-P_TawnC26v_/view?usp=drive_link | J25: https://drive.google.com/file/d/1khT69iSFS9yKmopFecHWmFYSdWSNDYYK/view?usp=drive_link
A26: A25 | B26: Barium Klorida Dihidrat | C26: BaCl₂.2 H₂O | D26: 1.01719.1000 - Supelco | E26: 1000 | F26: gram | G26: 100 | H26: SO4 | I26: https://drive.google.com/file/d/1Fxb3_5Us98a_Yx4EmAJS8XaTN-LPb9UK/view?usp=drive_link | J26: https://drive.google.com/file/d/1MTSlAXx9_pcYmg2fEQzhYzNnYEMzZOQe/view?usp=drive_link
A27: A26 | B27: Amonium klorida | C27: NH4Cl | D27: 1.01145.0500 - Supelco | E27: 500 | F27: gram | G27: 250 | H27: NH3-LC, NO3, | I27: https://drive.google.com/file/d/17NhN6YHTpkYN460kIXgadRQwtVlrE60X/view?usp=drive_link | J27: https://drive.google.com/file/d/1imnLgZJfoRGjZ-lYpNsefGSNK2rUleFe/view?usp=drive_link
A28: A27 | B28: 4-Aminoantipyrine 99% Extra Pure | C28: C11H13N3O | D28: 1030 - LobaChemie | E28: 25 | F28: gram | G28: 10 | H28: Fenol | I28: https://drive.google.com/file/d/1fe46woaLI4ud8qugB5uBUuQ5fZasNhlC/view?usp=drive_link | J28: https://drive.google.com/file/d/1Nvay6PZdCTkvYxWc_ftXGrN2pNWsq8xu/view?usp=drive_link
A29: A28 | B29: Sodium Azide AR | C29: NaN3 | D29: 5782 - LobaChemie | E29: 100 | F29: gram | G29: 50 | H29: BOD | I29: https://drive.google.com/file/d/1K04vVPmwq_ndk8fuHABTMq7afz9vIXiI/view?usp=drive_link | J29: https://drive.google.com/file/d/1oTQokXMBOpZXZfwTEnL85jv3kLXKAM6Q/view?usp=drive_link
A30: A29 | B30: Ammonium Molydate Tetrahydrate | C30: (NH4)6Mo7O24.4H2O | D30: 1271 - LobaChemie | E30: 100 | F30: gram | G30: 50 | H30: PO4, | I30: https://drive.google.com/file/d/1A4YZSFZMNuM1cMNUkuIa4nYFe20ID85L/view?usp=drive_link | J30: https://drive.google.com/file/d/1iE-lO8JJLNSPI7_dCMI8fh65GhMGamNo/view?usp=drive_link
A31: A30 | B31: Pararosaniline Chloride Extra Pure | C31: C19H18ClN3 | D31: 5129B - LobaChemie | E31: 25 | F31: gram | G31: 10 | H31: SO2 UA, | I31: https://drive.google.com/file/d/1rPcrNAW8rNU_Ems-dC2ur4d5ycds2IVn/view?usp=drive_link | J31: https://drive.google.com/file/d/1IM_S0bow3EzSYT9nGg5la-SyRdjLZs9S/view?usp=drive_link
A32: A31 | B32: Zirconium Oxychloride Octahydrate | C32: ZrOCl2.8H2O | D32: 6569 - LobaChemie | E32: 100 | F32: gram | G32: 50 | H32: F-LC, | I32: ZIRCONIUM OXYCHLORIDE OCTAHYDRATE AR | J32: https://drive.google.com/file/d/1Al5YqR5ve6fLiTPA4_RjfgTJLyT8TPRs/view?usp=drive_link
A33: A32 | B33: Sodium Nitroprusside Dihydrate | C33: Na2[Fe(CN)5NO].2H2O | D33: 5958 - LobaChemie | E33: 100 | F33: gram | G33: 50 | H33: NH3-UA, NH3-LC, NH3-UE, | I33: https://drive.google.com/file/d/14XE_k2mD9dPLwC8DdbYsxniVf8xqNof-/view?usp=drive_link | J33: https://drive.google.com/file/d/1sW6e68t7NY9VTf-3reqfal9olsryYmRh/view?usp=drive_link
A34: A33 | B34: Sodium Sulphite Anhydrous | C34: Na2SO3 | D34: 6024 - LobaChemie | E34: 500 | F34: gram | G34: 250 | H34: H2S,SO2 UA | I34: https://drive.google.com/file/d/1Tqqv2I_BTDm-S0M-c19PrIzn7cvRa4mw/view?usp=drive_link | J34: https://drive.google.com/file/d/1JFLCcjGAljdbn9gXMoVwcwUW8NMq_PFJ/view?usp=drive_link
A35: A34 | B35: Tri-Sodium Citrate Dihydrate | C35: C6H5Na3O7.2H2O | D35: 5835 - LobaChemie | E35: 500 | F35: gram | G35: 250 | H35: NH3-LC | I35: https://drive.google.com/file/d/1-3wxipAd_ICqM1sfvN39ORdkYRgauGTw/view?usp=drive_link | J35: https://drive.google.com/file/d/1dTNqSdc5afQIUqSd6SDyxGwLC4kGlQEp/view?usp=drive_link
... A63: A62 | B63: Sodium Bisulphite | C63: NaHSO3 | D63: 05799 - LobaChemie | E63: 500 | F63: gram | G63: 250 | H63: Formaldehyde | I63: https://drive.google.com/open?id=16Gfl9rk91T2x0yAIIx5VjblqMUKdI75L | J63: https://drive.google.com/file/d/1vvZ8WEOALl42pkV2z86TsVSxEZOVZ8NR/view?usp=drive_link
A64: A63 | B64: Zinc Acetate Dihydrate 99.5% | C64: (CH3.COO)2Zn.2H2O | D64: 06541 - LobaChemie | E64: 500 | F64: gram | G64: 250 | I64: https://drive.google.com/open?id=1kIBZ9C_bEJnY493X6c02azgV6a9o_kxK | J64: https://drive.google.com/file/d/1FT_6MUTK4-C-girDvLpL-En_fJJPYEeV/view?usp=drive_link
A65: A64 | B65: N,N-Dimethyl-1,4-phenylenediamine oxalate | C65: [(CH3)2NC6H4NH2]2·H2C2O4 | D65: 4.09758.025 SigmaAldrich | E65: 25 | F65: gram | G65: 10 | H65: Sulfida | I65: N,N-Dimethyl-1,4-phenylenediamine oxalate | J65: https://drive.google.com/file/d/1WC0M2sS0BfsJSKxLjgphZyZKs3WrhhNQ/view?usp=drive_link
A66: A65 | B66: Iodine | C66: I2 | D66: 2.07772.0100 - SigmaAldrich | E66: 100 | F66: gram | G66: 50 | H66: H2S, SO2 UA | I66: https://drive.google.com/open?id=1lT5KjrdgN-QIY9Lf_SHbYBtUiZACgjLH | J66: https://drive.google.com/file/d/13mrIByEsfxG7MvCilxt0c0n_nn7yGBZQ/view?usp=drive_link
A67: A66 | B67: Ammonium Phospahte dibasic | C67: H9N2O4P | D67: 1003721150 - SigmaAldrich | E67: 500 | F67: gram | G67: 50 | H67: H2S | I67: https://drive.google.com/open?id=1gYxXquexNBeal36jMq3WSkSNObhqknKy | J67: https://drive.google.com/file/d/1Lj0Rre1Z_gIPZ5es8yUbzU8ClKyQYYB5/view?usp=drive_link
A68: A67 | B68: Iron (III) chloride | C68: FeCl3 | D68: 1.57740.100 - SigmaAldrich | E68: 100 | F68: gram | G68: 50 | I68: https://drive.google.com/open?id=1b2gkillwFQNYVr1a5nLziZs6JhagNiHn | J68: https://drive.google.com/file/d/1DrrgGsVC1m3NJOw9IlM3D-nSQ9aZ2vAs/view?usp=drive_link
A69: A68 | B69: N-Allylthiourea | C69: C4H8N2S | D69: 1.08804.050 - SigmaAldrich | E69: 50 | F69: gram | G69: 10 | H69: BOD | I69: https://drive.google.com/open?id=1FzXOXeUIFPOwxc-SUYGI4wmaWQgCRZU1 | J69: https://drive.google.com/file/d/1ct7jHLQtff_0nnlH8FbF4S17S7tuBtzD/view?usp=drive_link
A70: A69 | B70: Sodium Borohydride | C70: H4BNa | D70: 4.52882.0500 - SigmaAldrich | E70: 500 | F70: gram | G70: 100 | I70: https://drive.google.com/open?id=1ArXDvOWFiTahfTWJf1YElCmPpm7zuGV0 | J70: https://drive.google.com/file/d/1Zyl3er20C8rtp0Ftk4jtD2aoARs1zyFV/view?usp=drive_link
A71: A70 | B71: Tryptic soy agar Casein-peptone soymealpeptone agar | C71: - | D71: 1.05458.0500 - Millipore | E71: 500 | F71: gram | G71: 100 | H71: Uji Kinerja Mikrobiologi | I71: https://drive.google.com/file/d/1ST40V_gYLA9qpoT6jdDOBzT3bmwXdSug/view?usp=drive_link | J71: https://drive.google.com/file/d/16dTHQ91GttoM6Oo_0Qee4c-hoA6v1lPU/view?usp=drive_link
...

Sheet Kartu Stock
C1: Laboratorium Penguji PT Sentral Sistem Laboratory | K1: SSL-FR-6.6.8; Rev.00; 02 September 2024
C2: Kartu Stok Alat dan Bahan
A4: No. | B4: Kode Barang | C4: Nama Bahan kimia | D4: Rumus Kimia | E4: Qty/Pack | F4: Unit/Pack | G4: Min. Qty | H4: Actual Qty | I4: Total Incoming | J4: Total Usage | K4: Status | L4: Jika Limited Stock, PO Number | M4: Ket | N4: Kegunaan Analisa
A5: 1 | B5: A1 | C5: =IFERROR(VLOOKUP(B5,'Spesifikasi Bahan'!$A$2:$B$10074,2,FALSE),"") -> Stearic Acid | D5: =IFERROR(VLOOKUP(B5,'Spesifikasi Bahan'!$A$2:$C$10074,3,FALSE),"") -> C18H36O2 | E5: =IFERROR(VLOOKUP(B5,'Spesifikasi Bahan'!$A$2:$E$10074,5,FALSE),"") -> 500 | F5: =IFERROR(VLOOKUP(B5,'Spesifikasi Bahan'!$A$2:$F$10074,6,FALSE),"") -> gram | G5: =IFERROR(VLOOKUP(B5,'Spesifikasi Bahan'!$A$2:$G$10074,7,FALSE),"") -> 250 | H5: =I5-J5 -> 598.6 | I5: =SUMIF('Form Responses Incoming'!$C$2:$C$10131,B5,'Form Responses Incoming'!$D$2:D10131) -> 600 | J5: =SUMIF('Form Responses Usage'!$C$2:$C$11115,B5,'Form Responses Usage'!$D$2:$D$11115) -> 1.4 | K5: =IF(H5<G5,"Limited Stock","OK") -> OK | L5: =IFERROR(VLOOKUP(B5,'Spesifikasi Bahan'!$A$2:$D$10074,4,FALSE),"") -> 1.75366.0100 SigmaAldrich | N5: #N/A
A6: 2 | B6: A2 | C6: =IFERROR(VLOOKUP(B6,'Spesifikasi Bahan'!$A$2:$B$10074,2,FALSE),"") -> 1,8-Dihydroxy-2-(4-Sulfophenylazo)-Naphthalen-3,6-Disulfonic Acid Trisodium Salt/SPADNS | D6: =IFERROR(VLOOKUP(B6,'Spesifikasi Bahan'!$A$2:$C$10074,3,FALSE),"") -> - | E6: =IFERROR(VLOOKUP(B6,'Spesifikasi Bahan'!$A$2:$E$10074,5,FALSE),"") -> 25 | F6: =IFERROR(VLOOKUP(B6,'Spesifikasi Bahan'!$A$2:$F$10074,6,FALSE),"") -> gram | G6: =IFERROR(VLOOKUP(B6,'Spesifikasi Bahan'!$A$2:$G$10074,7,FALSE),"") -> 10 | H6: =I6-J6 -> 496.6455 | I6: =SUMIF('Form Responses Incoming'!$C$2:$C$10131,B6,'Form Responses Incoming'!$D$2:D10132) -> 500 | J6: =SUMIF('Form Responses Usage'!$C$2:$C$11115,B6,'Form Responses Usage'!$D$2:$D$11115) -> 3.3545 | K6: =IF(H6<G6,"Limited Stock","OK") -> OK | L6: =IFERROR(VLOOKUP(B6,'Spesifikasi Bahan'!$A$2:$D$10074,4,FALSE),"") -> 1.07998.0025 - SigmaAldrich | N6: #N/A
A7: 3 | B7: A3 | C7: =IFERROR(VLOOKUP(B7,'Spesifikasi Bahan'!$A$2:$B$10074,2,FALSE),"") -> N-(1-Naphtyl)ethylenediamine dihydrochloride NEDA | D7: =IFERROR(VLOOKUP(B7,'Spesifikasi Bahan'!$A$2:$C$10074,3,FALSE),"") -> - | E7: =IFERROR(VLOOKUP(B7,'Spesifikasi Bahan'!$A$2:$E$10074,5,FALSE),"") -> 25 | F7: =IFERROR(VLOOKUP(B7,'Spesifikasi Bahan'!$A$2:$F$10074,6,FALSE),"") -> gram | G7: =IFERROR(VLOOKUP(B7,'Spesifikasi Bahan'!$A$2:$G$10074,7,FALSE),"") -> 10 | H7: =I7-J7 -> 21.896 | I7: =SUMIF('Form Responses Incoming'!$C$2:$C$10131,B7,'Form Responses Incoming'!$D$2:D10133) -> 25 | J7: =SUMIF('Form Responses Usage'!$C$2:$C$11115,B7,'Form Responses Usage'!$D$2:$D$11115) -> 3.104 | K7: =IF(H7<G7,"Limited Stock","OK") -> OK | L7: =IFERROR(VLOOKUP(B7,'Spesifikasi Bahan'!$A$2:$D$10074,4,FALSE),"") -> 1.06237.0025 - SigmaAldrich | N7: #N/A
A8: 4 | B8: A4 | C8: =IFERROR(VLOOKUP(B8,'Spesifikasi Bahan'!$A$2:$B$10074,2,FALSE),"") -> Butir Cadmium | D8: =IFERROR(VLOOKUP(B8,'Spesifikasi Bahan'!$A$2:$C$10074,3,FALSE),"") -> Cd | E8: =IFERROR(VLOOKUP(B8,'Spesifikasi Bahan'!$A$2:$E$10074,5,FALSE),"") -> 250 | F8: =IFERROR(VLOOKUP(B8,'Spesifikasi Bahan'!$A$2:$F$10074,6,FALSE),"") -> gram | G8: =IFERROR(VLOOKUP(B8,'Spesifikasi Bahan'!$A$2:$G$10074,7,FALSE),"") -> 100 | H8: =I8-J8 -> 425 | I8: =SUMIF('Form Responses Incoming'!$C$2:$C$10131,B8,'Form Responses Incoming'!$D$2:D10134) -> 500 | J8: =SUMIF('Form Responses Usage'!$C$2:$C$11115,B8,'Form Responses Usage'!$D$2:$D$11115) -> 75 | K8: =IF(H8<G8,"Limited Stock","OK") -> OK | L8: =IFERROR(VLOOKUP(B8,'Spesifikasi Bahan'!$A$2:$D$10074,4,FALSE),"") -> 1.02001.0250 - SigmaAldrich | N8: #N/A
A9: 5 | B9: A5 | C9: =IFERROR(VLOOKUP(B9,'Spesifikasi Bahan'!$A$2:$B$10074,2,FALSE),"") -> L-Glutamic Acid | D9: =IFERROR(VLOOKUP(B9,'Spesifikasi Bahan'!$A$2:$C$10074,3,FALSE),"") -> C5H9NO4 | E9: =IFERROR(VLOOKUP(B9,'Spesifikasi Bahan'!$A$2:$E$10074,5,FALSE),"") -> 250 | F9: =IFERROR(VLOOKUP(B9,'Spesifikasi Bahan'!$A$2:$F$10074,6,FALSE),"") -> gram | G9: =IFERROR(VLOOKUP(B9,'Spesifikasi Bahan'!$A$2:$G$10074,7,FALSE),"") -> 100 | H9: =I9-J9 -> 116.3578 | I9: =SUMIF('Form Responses Incoming'!$C$2:$C$10131,B9,'Form Responses Incoming'!$D$2:D10135) -> 250 | J9: =SUMIF('Form Responses Usage'!$C$2:$C$11115,B9,'Form Responses Usage'!$D$2:$D$11115) -> 133.6422 | K9: =IF(H9<G9,"Limited Stock","OK") -> OK | L9: =IFERROR(VLOOKUP(B9,'Spesifikasi Bahan'!$A$2:$D$10074,4,FALSE),"") -> 1.00291.0250 - SigmaAldrich | N9: #N/A
A10: 6 | B10: A6 | C10: =IFERROR(VLOOKUP(B10,'Spesifikasi Bahan'!$A$2:$B$10074,2,FALSE),"") -> Starch Soluble | D10: =IFERROR(VLOOKUP(B10,'Spesifikasi Bahan'!$A$2:$C$10074,3,FALSE),"") -> (C₆H₁₀O₅)n | E10: =IFERROR(VLOOKUP(B10,'Spesifikasi Bahan'!$A$2:$E$10074,5,FALSE),"") -> 100 | F10: =IFERROR(VLOOKUP(B10,'Spesifikasi Bahan'!$A$2:$F$10074,6,FALSE),"") -> gram | G10: =IFERROR(VLOOKUP(B10,'Spesifikasi Bahan'!$A$2:$G$10074,7,FALSE),"") -> 10 | H10: =I10-J10 -> 98.073 | I10: =SUMIF('Form Responses Incoming'!$C$2:$C$10131,B10,'Form Responses Incoming'!$D$2:D10136) -> 100 | J10: =SUMIF('Form Responses Usage'!$C$2:$C$11115,B10,'Form Responses Usage'!$D$2:$D$11115) -> 1.927 | K10: =IF(H10<G10,"Limited Stock","OK") -> OK | L10: =IFERROR(VLOOKUP(B10,'Spesifikasi Bahan'!$A$2:$D$10074,4,FALSE),"") -> 1.01252.0100 - Merck | N10: #N/A
A11: 7 | B11: A7 | C11: =IFERROR(VLOOKUP(B11,'Spesifikasi Bahan'!$A$2:$B$10074,2,FALSE),"") -> Tembaga(II) Sulfat Pentahidrat | D11: =IFERROR(VLOOKUP(B11,'Spesifikasi Bahan'!$A$2:$C$10074,3,FALSE),"") -> CuSO4.5H2O | E11: =IFERROR(VLOOKUP(B11,'Spesifikasi Bahan'!$A$2:$E$10074,5,FALSE),"") -> 1000 | F11: =IFERROR(VLOOKUP(B11,'Spesifikasi Bahan'!$A$2:$F$10074,6,FALSE),"") -> gram | G11: =IFERROR(VLOOKUP(B11,'Spesifikasi Bahan'!$A$2:$G$10074,7,FALSE),"") -> 250 | H11: =I11-J11 -> 965 | I11: =SUMIF('Form Responses Incoming'!$C$2:$C$10131,B11,'Form Responses Incoming'!$D$2:D10137) -> 1025 | J11: =SUMIF('Form Responses Usage'!$C$2:$C$11115,B11,'Form Responses Usage'!$D$2:$D$11115) -> 60 | K11: =IF(H11<G11,"Limited Stock","OK") -> OK | L11: =IFERROR(VLOOKUP(B11,'Spesifikasi Bahan'!$A$2:$D$10074,4,FALSE),"") -> A-2002 - Smartlab | N11: #N/A
A12: 8 | B12: A8 | C12: =IFERROR(VLOOKUP(B12,'Spesifikasi Bahan'!$A$2:$B$10074,2,FALSE),"") -> Magnesium Chloride Hexahydrate | D12: =IFERROR(VLOOKUP(B12,'Spesifikasi Bahan'!$A$2:$C$10074,3,FALSE),"") -> MgCl2.6H2O | E12: =IFERROR(VLOOKUP(B12,'Spesifikasi Bahan'!$A$2:$E$10074,5,FALSE),"") -> 250 | F12: =IFERROR(VLOOKUP(B12,'Spesifikasi Bahan'!$A$2:$F$10074,6,FALSE),"") -> gram | G12: =IFERROR(VLOOKUP(B12,'Spesifikasi Bahan'!$A$2:$G$10074,7,FALSE),"") -> 100 | H12: =I12-J12 -> 304.9894 | I12: =SUMIF('Form Responses Incoming'!$C$2:$C$10131,B12,'Form Responses Incoming'!$D$2:D10138) -> 500 | J12: =SUMIF('Form Responses Usage'!$C$2:$C$11115,B12,'Form Responses Usage'!$D$2:$D$11115) -> 195.0106 | K12: =IF(H12<G12,"Limited Stock","OK") -> OK | L12: =IFERROR(VLOOKUP(B12,'Spesifikasi Bahan'!$A$2:$D$10074,4,FALSE),"") -> 1.05833.0250 - Merck | N12: #N/A
A13: 9 | B13: A9 | C13: =IFERROR(VLOOKUP(B13,'Spesifikasi Bahan'!$A$2:$B$10074,2,FALSE),"") -> Potasium Iodida | D13: =IFERROR(VLOOKUP(B13,'Spesifikasi Bahan'!$A$2:$C$10074,3,FALSE),"") -> KI | E13: =IFERROR(VLOOKUP(B13,'Spesifikasi Bahan'!$A$2:$E$10074,5,FALSE),"") -> 500 | F13: =IFERROR(VLOOKUP(B13,'Spesifikasi Bahan'!$A$2:$F$10074,6,FALSE),"") -> gram | G13: =IFERROR(VLOOKUP(B13,'Spesifikasi Bahan'!$A$2:$G$10074,7,FALSE),"") -> 10 | H13: =I13-J13 -> 448.9888 | I13: =SUMIF('Form Responses Incoming'!$C$2:$C$10131,B13,'Form Responses Incoming'!$D$2:D10139) -> 500 | J13: =SUMIF('Form Responses Usage'!$C$2:$C$11115,B13,'Form Responses Usage'!$D$2:$D$11115) -> 51.0112 | K13: =IF(H13<G13,"Limited Stock","OK") -> OK | L13: =IFERROR(VLOOKUP(B13,'Spesifikasi Bahan'!$A$2:$D$10074,4,FALSE),"") -> A-2039 - Smart - Lab | N13: #N/A
A14: 10 | B14: A10 | C14: =IFERROR(VLOOKUP(B14,'Spesifikasi Bahan'!$A$2:$B$10074,2,FALSE),"") -> orto-Asam Fosfor 85% | D14: =IFERROR(VLOOKUP(B14,'Spesifikasi Bahan'!$A$2:$C$10074,3,FALSE),"") -> (COOH)₂.2 H₂O | E14: =IFERROR(VLOOKUP(B14,'Spesifikasi Bahan'!$A$2:$E$10074,5,FALSE),"") -> 500 | F14: =IFERROR(VLOOKUP(B14,'Spesifikasi Bahan'!$A$2:$F$10074,6,FALSE),"") -> gram | G14: =IFERROR(VLOOKUP(B14,'Spesifikasi Bahan'!$A$2:$G$10074,7,FALSE),"") -> 50 | H14: =I14-J14 -> 524.3698 | I14: =SUMIF('Form Responses Incoming'!$C$2:$C$10131,B14,'Form Responses Incoming'!$D$2:D10140) -> 525 | J14: =SUMIF('Form Responses Usage'!$C$2:$C$11115,B14,'Form Responses Usage'!$D$2:$D$11115) -> 0.6302 | K14: =IF(H14<G14,"Limited Stock","OK") -> OK | L14: =IFERROR(VLOOKUP(B14,'Spesifikasi Bahan'!$A$2:$D$10074,4,FALSE),"") -> 05074 - LobaChemie | N14: #N/A
A15: 11 | B15: A11 | C15: =IFERROR(VLOOKUP(B15,'Spesifikasi Bahan'!$A$2:$B$10074,2,FALSE),"") -> Potasium Klorida | D15: =IFERROR(VLOOKUP(B15,'Spesifikasi Bahan'!$A$2:$C$10074,3,FALSE),"") -> KCl | E15: =IFERROR(VLOOKUP(B15,'Spesifikasi Bahan'!$A$2:$E$10074,5,FALSE),"") -> 500 | F15: =IFERROR(VLOOKUP(B15,'Spesifikasi Bahan'!$A$2:$F$10074,6,FALSE),"") -> gram | G15: =IFERROR(VLOOKUP(B15,'Spesifikasi Bahan'!$A$2:$G$10074,7,FALSE),"") -> 10 | H15: =I15-J15 -> 300 | I15: =SUMIF('Form Responses Incoming'!$C$2:$C$10131,B15,'Form Responses Incoming'!$D$2:D10141) -> 300 | J15: =SUMIF('Form Responses Usage'!$C$2:$C$11115,B15,'Form Responses Usage'!$D$2:$D$11115) -> 0 | K15: =IF(H15<G15,"Limited Stock","OK") -> OK | L15: =IFERROR(VLOOKUP(B15,'Spesifikasi Bahan'!$A$2:$D$10074,4,FALSE),"") -> 1.04936.0250 - SigmaAldrich | N15: #N/A
A16: 12 | B16: A12 | C16: =IFERROR(VLOOKUP(B16,'Spesifikasi Bahan'!$A$2:$B$10074,2,FALSE),"") -> Potasium Iodat | D16: =IFERROR(VLOOKUP(B16,'Spesifikasi Bahan'!$A$2:$C$10074,3,FALSE),"") -> KIO₃ | E16: =IFERROR(VLOOKUP(B16,'Spesifikasi Bahan'!$A$2:$E$10074,5,FALSE),"") -> 100 | F16: =IFERROR(VLOOKUP(B16,'Spesifikasi Bahan'!$A$2:$F$10074,6,FALSE),"") -> gram | G16: =IFERROR(VLOOKUP(B16,'Spesifikasi Bahan'!$A$2:$G$10074,7,FALSE),"") -> 50 | H16: =I16-J16 -> 101.8165 | I16: =SUMIF('Form Responses Incoming'!$C$2:$C$10131,B16,'Form Responses Incoming'!$D$2:D10142) -> 105 | J16: =SUMIF('Form Responses Usage'!$C$2:$C$11115,B16,'Form Responses Usage'!$D$2:$D$11115) -> 3.1835 | K16: =IF(H16<G16,"Limited Stock","OK") -> OK | L16: =IFERROR(VLOOKUP(B16,'Spesifikasi Bahan'!$A$2:$D$10074,4,FALSE),"") -> 215929.0100 SigmaAldrich | M16: bahan pendukung, di hold | N16: #N/A
A17: 13 | B17: A13 | C17: =IFERROR(VLOOKUP(B17,'Spesifikasi Bahan'!$A$2:$B$10074,2,FALSE),"") -> Potasium Kromat | D17: =IFERROR(VLOOKUP(B17,'Spesifikasi Bahan'!$A$2:$C$10074,3,FALSE),"") -> K₂CrO₄ | E17: =IFERROR(VLOOKUP(B17,'Spesifikasi Bahan'!$A$2:$E$10074,5,FALSE),"") -> 100 | F17: =IFERROR(VLOOKUP(B17,'Spesifikasi Bahan'!$A$2:$F$10074,6,FALSE),"") -> gram | G17: =IFERROR(VLOOKUP(B17,'Spesifikasi Bahan'!$A$2:$G$10074,7,FALSE),"") -> 10 | H17: =I17-J17 -> 60 | I17: =SUMIF('Form Responses Incoming'!$C$2:$C$10131,B17,'Form Responses Incoming'!$D$2:D10143) -> 110 | J17: =SUMIF('Form Responses Usage'!$C$2:$C$11115,B17,'Form Responses Usage'!$D$2:$D$11115) -> 50 | K17: =IF(H17<G17,"Limited Stock","OK") -> OK | L17: =IFERROR(VLOOKUP(B17,'Spesifikasi Bahan'!$A$2:$D$10074,4,FALSE),"") -> 05344 - LobaChemie | N17: #N/A
A18: 14 | B18: A14 | C18: =IFERROR(VLOOKUP(B18,'Spesifikasi Bahan'!$A$2:$B$10074,2,FALSE),"") -> Dodecyl Sulfate Sodium Salt | D18: =IFERROR(VLOOKUP(B18,'Spesifikasi Bahan'!$A$2:$C$10074,3,FALSE),"") -> C12H25NaO4S | E18: =IFERROR(VLOOKUP(B18,'Spesifikasi Bahan'!$A$2:$E$10074,5,FALSE),"") -> 105 | F18: =IFERROR(VLOOKUP(B18,'Spesifikasi Bahan'!$A$2:$F$10074,6,FALSE),"") -> gram | G18: =IFERROR(VLOOKUP(B18,'Spesifikasi Bahan'!$A$2:$G$10074,7,FALSE),"") -> 10 | H18: =I18-J18 -> 104 | I18: =SUMIF('Form Responses Incoming'!$C$2:$C$10131,B18,'Form Responses Incoming'!$D$2:D10144) -> 105 | J18: =SUMIF('Form Responses Usage'!$C$2:$C$11115,B18,'Form Responses Usage'!$D$2:$D$11115) -> 1 | K18: =IF(H18<G18,"Limited Stock","OK") -> OK | L18: =IFERROR(VLOOKUP(B18,'Spesifikasi Bahan'!$A$2:$D$10074,4,FALSE),"") -> 1.13760.0100 - SigmaAldrich | N18: #N/A
A19: 15 | B19: A15 | C19: =IFERROR(VLOOKUP(B19,'Spesifikasi Bahan'!$A$2:$B$10074,2,FALSE),"") -> Sulfanilamide | D19: =IFERROR(VLOOKUP(B19,'Spesifikasi Bahan'!$A$2:$C$10074,3,FALSE),"") -> C₆H₈N₂O₂S | E19: =IFERROR(VLOOKUP(B19,'Spesifikasi Bahan'!$A$2:$E$10074,5,FALSE),"") -> 100 | F19: =IFERROR(VLOOKUP(B19,'Spesifikasi Bahan'!$A$2:$F$10074,6,FALSE),"") -> gram | G19: =IFERROR(VLOOKUP(B19,'Spesifikasi Bahan'!$A$2:$G$10074,7,FALSE),"") -> 50 | H19: =I19-J19 -> 95 | I19: =SUMIF('Form Responses Incoming'!$C$2:$C$10131,B19,'Form Responses Incoming'!$D$2:D10145) -> 105 | J19: =SUMIF('Form Responses Usage'!$C$2:$C$11115,B19,'Form Responses Usage'!$D$2:$D$11115) -> 10 | K19: =IF(H19<G19,"Limited Stock","OK") -> OK | L19: =IFERROR(VLOOKUP(B19,'Spesifikasi Bahan'!$A$2:$D$10074,4,FALSE),"") -> 1.11799.0100 - Merck | N19: #N/A
A20: 16 | B20: A16 | C20: =IFERROR(VLOOKUP(B20,'Spesifikasi Bahan'!$A$2:$B$10074,2,FALSE),"") -> Kalium Antimon(III) Oksida Tartrat Trihidrat | D20: =IFERROR(VLOOKUP(B20,'Spesifikasi Bahan'!$A$2:$C$10074,3,FALSE),"") -> K₂(SbO)₂C₈H₄O₁₀ . 3 H₂O | E20: =IFERROR(VLOOKUP(B20,'Spesifikasi Bahan'!$A$2:$E$10074,5,FALSE),"") -> 250 | F20: =IFERROR(VLOOKUP(B20,'Spesifikasi Bahan'!$A$2:$F$10074,6,FALSE),"") -> gram | G20: =IFERROR(VLOOKUP(B20,'Spesifikasi Bahan'!$A$2:$G$10074,7,FALSE),"") -> 100 | H20: =I20-J20 -> 499.808 | I20: =SUMIF('Form Responses Incoming'!$C$2:$C$10131,B20,'Form Responses Incoming'!$D$2:D10146) -> 500 | J20: =SUMIF('Form Responses Usage'!$C$2:$C$11115,B20,'Form Responses Usage'!$D$2:$D$11115) -> 0.192 | K20: =IF(H20<G20,"Limited Stock","OK") -> OK | L20: =IFERROR(VLOOKUP(B20,'Spesifikasi Bahan'!$A$2:$D$10074,4,FALSE),"") -> 1.08092.0250 - Supelco | N20: #N/A
A21: 17 | B21: A17 | C21: =IFERROR(VLOOKUP(B21,'Spesifikasi Bahan'!$A$2:$B$10074,2,FALSE),"") -> Sulfanilic Acid | D21: =IFERROR(VLOOKUP(B21,'Spesifikasi Bahan'!$A$2:$C$10074,3,FALSE),"") -> NH₂C₆H₄SO₃H | E21: =IFERROR(VLOOKUP(B21,'Spesifikasi Bahan'!$A$2:$E$10074,5,FALSE),"") -> 100 | F21: =IFERROR(VLOOKUP(B21,'Spesifikasi Bahan'!$A$2:$F$10074,6,FALSE),"") -> gram | G21: =IFERROR(VLOOKUP(B21,'Spesifikasi Bahan'!$A$2:$G$10074,7,FALSE),"") -> 100 | H21: =I21-J21 -> 340 | I21: =SUMIF('Form Responses Incoming'!$C$2:$C$10131,B21,'Form Responses Incoming'!$D$2:D10147) -> 350 | J21: =SUMIF('Form Responses Usage'!$C$2:$C$11115,B21,'Form Responses Usage'!$D$2:$D$11115) -> 10 | K21: =IF(H21<G21,"Limited Stock","OK") -> OK | L21: =IFERROR(VLOOKUP(B21,'Spesifikasi Bahan'!$A$2:$D$10074,4,FALSE),"") -> 1.00686.0250 - Supelco | N21: #N/A
A22: 18 | B22: A18 | C22: =IFERROR(VLOOKUP(B22,'Spesifikasi Bahan'!$A$2:$B$10074,2,FALSE),"") -> Manganese (II) Sulfate Monohydrate | D22: =IFERROR(VLOOKUP(B22,'Spesifikasi Bahan'!$A$2:$C$10074,3,FALSE),"") -> MnSO₄.H₂O | E22: =IFERROR(VLOOKUP(B22,'Spesifikasi Bahan'!$A$2:$E$10074,5,FALSE),"") -> 250 | F22: =IFERROR(VLOOKUP(B22,'Spesifikasi Bahan'!$A$2:$F$10074,6,FALSE),"") -> gram | G22: =IFERROR(VLOOKUP(B22,'Spesifikasi Bahan'!$A$2:$G$10074,7,FALSE),"") -> 100 | H22: =I22-J22 -> 250 | I22: =SUMIF('Form Responses Incoming'!$C$2:$C$10131,B22,'Form Responses Incoming'!$D$2:D10148) -> 250 | J22: =SUMIF('Form Responses Usage'!$C$2:$C$11115,B22,'Form Responses Usage'!$D$2:$D$11115) -> 0 | K22: =IF(H22<G22,"Limited Stock","OK") -> OK | L22: =IFERROR(VLOOKUP(B22,'Spesifikasi Bahan'!$A$2:$D$10074,4,FALSE),"") -> 1.05941.0250 - Supelco | N22: #N/A
A23: 19 | B23: A19 | C23: =IFERROR(VLOOKUP(B23,'Spesifikasi Bahan'!$A$2:$B$10074,2,FALSE),"") -> Potasium Hidrogen Ptalat | D23: =IFERROR(VLOOKUP(B23,'Spesifikasi Bahan'!$A$2:$C$10074,3,FALSE),"") -> C₈H₅KO₄ | E23: =IFERROR(VLOOKUP(B23,'Spesifikasi Bahan'!$A$2:$E$10074,5,FALSE),"") -> 250 | F23: =IFERROR(VLOOKUP(B23,'Spesifikasi Bahan'!$A$2:$F$10074,6,FALSE),"") -> gram | G23: =IFERROR(VLOOKUP(B23,'Spesifikasi Bahan'!$A$2:$G$10074,7,FALSE),"") -> 100 | H23: =I23-J23 -> 246.9221 | I23: =SUMIF('Form Responses Incoming'!$C$2:$C$10131,B23,'Form Responses Incoming'!$D$2:D10149) -> 250 | J23: =SUMIF('Form Responses Usage'!$C$2:$C$11115,B23,'Form Responses Usage'!$D$2:$D$11115) -> 3.0779 | K23: =IF(H23<G23,"Limited Stock","OK") -> OK | L23: =IFERROR(VLOOKUP(B23,'Spesifikasi Bahan'!$A$2:$D$10074,4,FALSE),"") -> 1.04874.0250 - Supelco | N23: #N/A
A24: 20 | B24: A20 | C24: =IFERROR(VLOOKUP(B24,'Spesifikasi Bahan'!$A$2:$B$10074,2,FALSE),"") -> Potasium Nitrat | D24: =IFERROR(VLOOKUP(B24,'Spesifikasi Bahan'!$A$2:$C$10074,3,FALSE),"") -> KNO₃ | E24: =IFERROR(VLOOKUP(B24,'Spesifikasi Bahan'!$A$2:$E$10074,5,FALSE),"") -> 500 | F24: =IFERROR(VLOOKUP(B24,'Spesifikasi Bahan'!$A$2:$F$10074,6,FALSE),"") -> gram | G24: =IFERROR(VLOOKUP(B24,'Spesifikasi Bahan'!$A$2:$G$10074,7,FALSE),"") -> 250 | H24: =I24-J24 -> 493.0777 | I24: =SUMIF('Form Responses Incoming'!$C$2:$C$10131,B24,'Form Responses Incoming'!$D$2:D10150) -> 500 | J24: =SUMIF('Form Responses Usage'!$C$2:$C$11115,B24,'Form Responses Usage'!$D$2:$D$11115) -> 6.9223 | K24: =IF(H24<G24,"Limited Stock","OK") -> OK | L24: =IFERROR(VLOOKUP(B24,'Spesifikasi Bahan'!$A$2:$D$10074,4,FALSE),"") -> 1.05063.0500 - Supelco | N24: #N/A
A25: 21 | B25: A21 | C25: =IFERROR(VLOOKUP(B25,'Spesifikasi Bahan'!$A$2:$B$10074,2,FALSE),"") -> Di-Sodium Hidrogen Posfat Dodekahidrat | D25: =IFERROR(VLOOKUP(B25,'Spesifikasi Bahan'!$A$2:$C$10074,3,FALSE),"") -> Na₂HPO₄.12H₂O | E25: =IFERROR(VLOOKUP(B25,'Spesifikasi Bahan'!$A$2:$E$10074,5,FALSE),"") -> 500 | F25: =IFERROR(VLOOKUP(B25,'Spesifikasi Bahan'!$A$2:$F$10074,6,FALSE),"") -> gram | G25: =IFERROR(VLOOKUP(B25,'Spesifikasi Bahan'!$A$2:$G$10074,7,FALSE),"") -> 200 | H25: =I25-J25 -> 416.0895 | I25: =SUMIF('Form Responses Incoming'!$C$2:$C$10131,B25,'Form Responses Incoming'!$D$2:D10151) -> 500 | J25: =SUMIF('Form Responses Usage'!$C$2:$C$11115,B25,'Form Responses Usage'!$D$2:$D$11115) -> 83.9105 | K25: =IF(H25<G25,"Limited Stock","OK") -> OK | L25: =IFERROR(VLOOKUP(B25,'Spesifikasi Bahan'!$A$2:$D$10074,4,FALSE),"") -> 1.06579.0500 - Supelco | N25: #N/A
A26: 22 | B26: A22 | C26: =IFERROR(VLOOKUP(B26,'Spesifikasi Bahan'!$A$2:$B$10074,2,FALSE),"") -> Sodium Hidroksida | D26: =IFERROR(VLOOKUP(B26,'Spesifikasi Bahan'!$A$2:$C$10074,3,FALSE),"") -> NaOH | E26: =IFERROR(VLOOKUP(B26,'Spesifikasi Bahan'!$A$2:$E$10074,5,FALSE),"") -> 500 | F26: =IFERROR(VLOOKUP(B26,'Spesifikasi Bahan'!$A$2:$F$10074,6,FALSE),"") -> gram | G26: =IFERROR(VLOOKUP(B26,'Spesifikasi Bahan'!$A$2:$G$10074,7,FALSE),"") -> 250 | H26: =I26-J26 -> 1048.1895 | I26: =SUMIF('Form Responses Incoming'!$C$2:$C$10131,B26,'Form Responses Incoming'!$D$2:D10152) -> 1500 | J26: =SUMIF('Form Responses Usage'!$C$2:$C$11115,B26,'Form Responses Usage'!$D$2:$D$11115) -> 451.8105 | K26: =IF(H26<G26,"Limited Stock","OK") -> OK | L26: =IFERROR(VLOOKUP(B26,'Spesifikasi Bahan'!$A$2:$D$10074,4,FALSE),"") -> 1.06498.0500 - Supelco/ 605K6006 - Kanto Chemical | N26: #N/A
A27: 23 | B27: A23 | C27: =IFERROR(VLOOKUP(B27,'Spesifikasi Bahan'!$A$2:$B$10074,2,FALSE),"") -> Sodium Dihidrogen Posfat Monohidrat | D27: =IFERROR(VLOOKUP(B27,'Spesifikasi Bahan'!$A$2:$C$10074,3,FALSE),"") -> NaH₂PO₄.H₂O | E27: =IFERROR(VLOOKUP(B27,'Spesifikasi Bahan'!$A$2:$E$10074,5,FALSE),"") -> 1000 | F27: =IFERROR(VLOOKUP(B27,'Spesifikasi Bahan'!$A$2:$F$10074,6,FALSE),"") -> gram | G27: =IFERROR(VLOOKUP(B27,'Spesifikasi Bahan'!$A$2:$G$10074,7,FALSE),"") -> 500 | H27: =I27-J27 -> 832.4822 | I27: =SUMIF('Form Responses Incoming'!$C$2:$C$10131,B27,'Form Responses Incoming'!$D$2:D10153) -> 1000 | J27: =SUMIF('Form Responses Usage'!$C$2:$C$11115,B27,'Form Responses Usage'!$D$2:$D$11115) -> 167.5178 | K27: =IF(H27<G27,"Limited Stock","OK") -> OK | L27: =IFERROR(VLOOKUP(B27,'Spesifikasi Bahan'!$A$2:$D$10074,4,FALSE),"") -> 1.06346.1000 - Supelco | N27: #N/A
A28: 24 | B28: A24 | C28: =IFERROR(VLOOKUP(B28,'Spesifikasi Bahan'!$A$2:$B$10074,2,FALSE),"") -> Phenol | D28: =IFERROR(VLOOKUP(B28,'Spesifikasi Bahan'!$A$2:$C$10074,3,FALSE),"") -> C₆H₅OH | E28: =IFERROR(VLOOKUP(B28,'Spesifikasi Bahan'!$A$2:$E$10074,5,FALSE),"") -> 250 | F28: =IFERROR(VLOOKUP(B28,'Spesifikasi Bahan'!$A$2:$F$10074,6,FALSE),"") -> gram | G28: =IFERROR(VLOOKUP(B28,'Spesifikasi Bahan'!$A$2:$G$10074,7,FALSE),"") -> 100 | H28: =I28-J28 -> 325.2 | I28: =SUMIF('Form Responses Incoming'!$C$2:$C$10131,B28,'Form Responses Incoming'!$D$2:D10154) -> 750 | J28: =SUMIF('Form Responses Usage'!$C$2:$C$11115,B28,'Form Responses Usage'!$D$2:$D$11115) -> 424.8 | K28: =IF(H28<G28,"Limited Stock","OK") -> OK | L28: =IFERROR(VLOOKUP(B28,'Spesifikasi Bahan'!$A$2:$D$10074,4,FALSE),"") -> 1.00206.1000 - Supelco | N28: #N/A
... A65: 61 | B65: B19 | C65: =IFERROR(VLOOKUP(B65,'Spesifikasi Bahan'!$A$2:$B$10074,2,FALSE),"") -> Antimony Standard Solution | D65: =IFERROR(VLOOKUP(B65,'Spesifikasi Bahan'!$A$2:$C$10074,3,FALSE),"") -> Sb | E65: =IFERROR(VLOOKUP(B65,'Spesifikasi Bahan'!$A$2:$E$10074,5,FALSE),"") -> 500 | F65: =IFERROR(VLOOKUP(B65,'Spesifikasi Bahan'!$A$2:$F$10074,6,FALSE),"") -> mL | G65: =IFERROR(VLOOKUP(B65,'Spesifikasi Bahan'!$A$2:$G$10074,7,FALSE),"") -> 10 | H65: =I65-J65 -> 469 | I65: =SUMIF('Form Responses Incoming'!$C$2:$C$10131,B65,'Form Responses Incoming'!$D$2:D10191) -> 500 | J65: =SUMIF('Form Responses Usage'!$C$2:$C$11115,B65,'Form Responses Usage'!$D$2:$D$11115) -> 31 | K65: =IF(H65<G65,"Limited Stock","OK") -> OK | L65: =IFERROR(VLOOKUP(B65,'Spesifikasi Bahan'!$A$2:$D$10074,4,FALSE),"") -> 1.70204.0500 - Supelco | N65: #N/A
A66: 62 | B66: B20 | C66: =IFERROR(VLOOKUP(B66,'Spesifikasi Bahan'!$A$2:$B$10074,2,FALSE),"") -> Platinum Cobalt Standard Solution | D66: =IFERROR(VLOOKUP(B66,'Spesifikasi Bahan'!$A$2:$C$10074,3,FALSE),"") -> Pt-Co | E66: =IFERROR(VLOOKUP(B66,'Spesifikasi Bahan'!$A$2:$E$10074,5,FALSE),"") -> 250 | F66: =IFERROR(VLOOKUP(B66,'Spesifikasi Bahan'!$A$2:$F$10074,6,FALSE),"") -> mL | G66: 30 | H66: =I66-J66 -> 387.5 | I66: =SUMIF('Form Responses Incoming'!$C$2:$C$10131,B66,'Form Responses Incoming'!$D$2:D10192) -> 750 | J66: =SUMIF('Form Responses Usage'!$C$2:$C$11115,B66,'Form Responses Usage'!$D$2:$D$11115) -> 362.5 | K66: =IF(H66<G66,"Limited Stock","OK") -> OK | L66: =IFERROR(VLOOKUP(B66,'Spesifikasi Bahan'!$A$2:$D$10074,4,FALSE),"") -> 1.00246.0250 - Supelco | N66: #N/A
A67: 63 | B67: B21 | C67: =IFERROR(VLOOKUP(B67,'Spesifikasi Bahan'!$A$2:$B$10074,2,FALSE),"") -> Total Suspended Solid Calibration Standard | D67: =IFERROR(VLOOKUP(B67,'Spesifikasi Bahan'!$A$2:$C$10074,3,FALSE),"") -> TSS | E67: =IFERROR(VLOOKUP(B67,'Spesifikasi Bahan'!$A$2:$E$10074,5,FALSE),"") -> 100 | F67: =IFERROR(VLOOKUP(B67,'Spesifikasi Bahan'!$A$2:$F$10074,6,FALSE),"") -> mL | G67: =IFERROR(VLOOKUP(B67,'Spesifikasi Bahan'!$A$2:$G$10074,7,FALSE),"") -> 10 | H67: =I67-J67 -> 200 | I67: =SUMIF('Form Responses Incoming'!$C$2:$C$10131,B67,'Form Responses Incoming'!$D$2:D10193) -> 200 | J67: =SUMIF('Form Responses Usage'!$C$2:$C$11115,B67,'Form Responses Usage'!$D$2:$D$11115) -> 0 | K67: =IF(H67<G67,"Limited Stock","OK") -> OK | L67: =IFERROR(VLOOKUP(B67,'Spesifikasi Bahan'!$A$2:$D$10074,4,FALSE),"") -> TSS100 - SigmaAldrich | N67: #N/A
A68: 64 | B68: B22 | C68: =IFERROR(VLOOKUP(B68,'Spesifikasi Bahan'!$A$2:$B$10074,2,FALSE),"") -> Lead Standard Solution | D68: =IFERROR(VLOOKUP(B68,'Spesifikasi Bahan'!$A$2:$C$10074,3,FALSE),"") -> Pb | E68: =IFERROR(VLOOKUP(B68,'Spesifikasi Bahan'!$A$2:$E$10074,5,FALSE),"") -> 500 | F68: =IFERROR(VLOOKUP(B68,'Spesifikasi Bahan'!$A$2:$F$10074,6,FALSE),"") -> mL | G68: =IFERROR(VLOOKUP(B68,'Spesifikasi Bahan'!$A$2:$G$10074,7,FALSE),"") -> 10 | H68: =I68-J68 -> 474.65 | I68: =SUMIF('Form Responses Incoming'!$C$2:$C$10131,B68,'Form Responses Incoming'!$D$2:D10194) -> 500 | J68: =SUMIF('Form Responses Usage'!$C$2:$C$11115,B68,'Form Responses Usage'!$D$2:$D$11115) -> 25.35 | K68: =IF(H68<G68,"Limited Stock","OK") -> OK | L68: =IFERROR(VLOOKUP(B68,'Spesifikasi Bahan'!$A$2:$D$10074,4,FALSE),"") -> 1.19776.0500 - Supelco | N68: #N/A
A69: 65 | B69: B23 | C69: =IFERROR(VLOOKUP(B69,'Spesifikasi Bahan'!$A$2:$B$10074,2,FALSE),"") -> Nitric Acid | D69: =IFERROR(VLOOKUP(B69,'Spesifikasi Bahan'!$A$2:$C$10074,3,FALSE),"") -> HNO3 | E69: =IFERROR(VLOOKUP(B69,'Spesifikasi Bahan'!$A$2:$E$10074,5,FALSE),"") -> 2500 | F69: =IFERROR(VLOOKUP(B69,'Spesifikasi Bahan'!$A$2:$F$10074,6,FALSE),"") -> mL | G69: =IFERROR(VLOOKUP(B69,'Spesifikasi Bahan'!$A$2:$G$10074,7,FALSE),"") -> 500 | H69: =I69-J69 -> 2705.7 | I69: =SUMIF('Form Responses Incoming'!$C$2:$C$10131,B69,'Form Responses Incoming'!$D$2:D10195) -> 5000 | J69: =SUMIF('Form Responses Usage'!$C$2:$C$11115,B69,'Form Responses Usage'!$D$2:$D$11115) -> 2294.3 | K69: =IF(H69<G69,"Limited Stock","OK") -> OK | L69: =IFERROR(VLOOKUP(B69,'Spesifikasi Bahan'!$A$2:$D$10074,4,FALSE),"") -> A - 1063 - SmartLab AR1133-G2.5L - RCl Labscan | N69: #N/A
A70: 66 | B70: B24 | C70: =IFERROR(VLOOKUP(B70,'Spesifikasi Bahan'!$A$2:$B$10074,2,FALSE),"") -> Sulphuric Acid | D70: =IFERROR(VLOOKUP(B70,'Spesifikasi Bahan'!$A$2:$C$10074,3,FALSE),"") -> H2SO4 | E70: =IFERROR(VLOOKUP(B70,'Spesifikasi Bahan'!$A$2:$E$10074,5,FALSE),"") -> 2500 | F70: =IFERROR(VLOOKUP(B70,'Spesifikasi Bahan'!$A$2:$F$10074,6,FALSE),"") -> mL | G70: =IFERROR(VLOOKUP(B70,'Spesifikasi Bahan'!$A$2:$G$10074,7,FALSE),"") -> 500 | H70: =I70-J70 -> 4493.7 | I70: =SUMIF('Form Responses Incoming'!$C$2:$C$10131,B70,'Form Responses Incoming'!$D$2:D10196) -> 10500 | J70: =SUMIF('Form Responses Usage'!$C$2:$C$11115,B70,'Form Responses Usage'!$D$2:$D$11115) -> 6006.3 | K70: =IF(H70<G70,"Limited Stock","OK") -> OK | L70: =IFERROR(VLOOKUP(B70,'Spesifikasi Bahan'!$A$2:$D$10074,4,FALSE),"") -> A - 1092 - Smartlab, 0290C-LobaChemie, AR1193-G500ML - RCI Labscan | N70: #N/A
A71: 67 | B71: B25 | C71: =IFERROR(VLOOKUP(B71,'Spesifikasi Bahan'!$A$2:$B$10074,2,FALSE),"") -> Hydrochloric Acid | D71: =IFERROR(VLOOKUP(B71,'Spesifikasi Bahan'!$A$2:$C$10074,3,FALSE),"") -> HCl | E71: =IFERROR(VLOOKUP(B71,'Spesifikasi Bahan'!$A$2:$E$10074,5,FALSE),"") -> 2500 | F71: =IFERROR(VLOOKUP(B71,'Spesifikasi Bahan'!$A$2:$F$10074,6,FALSE),"") -> mL | G71: =IFERROR(VLOOKUP(B71,'Spesifikasi Bahan'!$A$2:$G$10074,7,FALSE),"") -> 100 | H71: =I71-J71 -> 4472.4 | I71: =SUMIF('Form Responses Incoming'!$C$2:$C$10131,B71,'Form Responses Incoming'!$D$2:D10197) -> 10000 | J71: =SUMIF('Form Responses Usage'!$C$2:$C$11115,B71,'Form Responses Usage'!$D$2:$D$11115) -> 5527.6 | K71: =IF(H71<G71,"Limited Stock","OK") -> OK | L71: =IFERROR(VLOOKUP(B71,'Spesifikasi Bahan'!$A$2:$D$10074,4,FALSE),"") -> A - 1050 - Smartlab AR1107-G2.5L - RCl Labscan | N71: #N/A
A72: 68 | B72: B26 | C72: =IFERROR(VLOOKUP(B72,'Spesifikasi Bahan'!$A$2:$B$10074,2,FALSE),"") -> Aceton | D72: =IFERROR(VLOOKUP(B72,'Spesifikasi Bahan'!$A$2:$C$10074,3,FALSE),"") -> (CH3)2CO | E72: =IFERROR(VLOOKUP(B72,'Spesifikasi Bahan'!$A$2:$E$10074,5,FALSE),"") -> 4000 | F72: =IFERROR(VLOOKUP(B72,'Spesifikasi Bahan'!$A$2:$F$10074,6,FALSE),"") -> mL | G72: =IFERROR(VLOOKUP(B72,'Spesifikasi Bahan'!$A$2:$G$10074,7,FALSE),"") -> 500 | H72: =I72-J72 -> 3675 | I72: =SUMIF('Form Responses Incoming'!$C$2:$C$10131,B72,'Form Responses Incoming'!$D$2:D10198) -> 8000 | J72: =SUMIF('Form Responses Usage'!$C$2:$C$11115,B72,'Form Responses Usage'!$D$2:$D$11115) -> 4325 | K72: =IF(H72<G72,"Limited Stock","OK") -> OK | L72: =IFERROR(VLOOKUP(B72,'Spesifikasi Bahan'!$A$2:$D$10074,4,FALSE),"") -> A - 1005 - SmartLab | N72: #N/A
A73: 69 | B73: B27 | C73: =IFERROR(VLOOKUP(B73,'Spesifikasi Bahan'!$A$2:$B$10074,2,FALSE),"") -> n-Hexane | D73: =IFERROR(VLOOKUP(B73,'Spesifikasi Bahan'!$A$2:$C$10074,3,FALSE),"") -> C6H14 | E73: =IFERROR(VLOOKUP(B73,'Spesifikasi Bahan'!$A$2:$E$10074,5,FALSE),"") -> 4000 | F73: =IFERROR(VLOOKUP(B73,'Spesifikasi Bahan'!$A$2:$F$10074,6,FALSE),"") -> mL | G73: =IFERROR(VLOOKUP(B73,'Spesifikasi Bahan'!$A$2:$G$10074,7,FALSE),"") -> 3000 | H73: =I73-J73 -> 3820 | I73: =SUMIF('Form Responses Incoming'!$C$2:$C$10131,B73,'Form Responses Incoming'!$D$2:D10199) -> 4000 | J73: =SUMIF('Form Responses Usage'!$C$2:$C$11115,B73,'Form Responses Usage'!$D$2:$D$11115) -> 180 | K73: =IF(H73<G73,"Limited Stock","OK") -> OK | L73: =IFERROR(VLOOKUP(B73,'Spesifikasi Bahan'!$A$2:$D$10074,4,FALSE),"") -> A - 1045 - SmartLab | N73: #N/A
A74: 70 | B74: B28 | C74: =IFERROR(VLOOKUP(B74,'Spesifikasi Bahan'!$A$2:$B$10074,2,FALSE),"") -> Chloroform | D74: =IFERROR(VLOOKUP(B74,'Spesifikasi Bahan'!$A$2:$C$10074,3,FALSE),"") -> CHCl3 | E74: =IFERROR(VLOOKUP(B74,'Spesifikasi Bahan'!$A$2:$E$10074,5,FALSE),"") -> 4000 | F74: =IFERROR(VLOOKUP(B74,'Spesifikasi Bahan'!$A$2:$F$10074,6,FALSE),"") -> mL | G74: =IFERROR(VLOOKUP(B74,'Spesifikasi Bahan'!$A$2:$G$10074,7,FALSE),"") -> 3000 | H74: =I74-J74 -> 3596 | I74: =SUMIF('Form Responses Incoming'!$C$2:$C$10131,B74,'Form Responses Incoming'!$D$2:D10200) -> 8000 | J74: =SUMIF('Form Responses Usage'!$C$2:$C$11115,B74,'Form Responses Usage'!$D$2:$D$11115) -> 4404 | K74: =IF(H74<G74,"Limited Stock","OK") -> OK | L74: =IFERROR(VLOOKUP(B74,'Spesifikasi Bahan'!$A$2:$D$10074,4,FALSE),"") -> A - 1022 - SmartLab dan 67663 - RCl Labscan | N74: #N/A
A75: 71 | B75: B29 | C75: =IFERROR(VLOOKUP(B75,'Spesifikasi Bahan'!$A$2:$B$10074,2,FALSE),"") -> Methanol | D75: =IFERROR(VLOOKUP(B75,'Spesifikasi Bahan'!$A$2:$C$10074,3,FALSE),"") -> CH3OH | E75: =IFERROR(VLOOKUP(B75,'Spesifikasi Bahan'!$A$2:$E$10074,5,FALSE),"") -> 4000 | F75: =IFERROR(VLOOKUP(B75,'Spesifikasi Bahan'!$A$2:$F$10074,6,FALSE),"") -> mL | G75: =IFERROR(VLOOKUP(B75,'Spesifikasi Bahan'!$A$2:$G$10074,7,FALSE),"") -> 1000 | H75: =I75-J75 -> 6705 | I75: =SUMIF('Form Responses Incoming'!$C$2:$C$10131,B75,'Form Responses Incoming'!$D$2:D10201) -> 8000 | J75: =SUMIF('Form Responses Usage'!$C$2:$C$11115,B75,'Form Responses Usage'!$D$2:$D$11115) -> 1295 | K75: =IF(H75<G75,"Limited Stock","OK") -> OK | L75: =IFERROR(VLOOKUP(B75,'Spesifikasi Bahan'!$A$2:$D$10074,4,FALSE),"") -> A - 1056 - SmartLab | N75: #N/A
A76: 72 | B76: B30 | C76: =IFERROR(VLOOKUP(B76,'Spesifikasi Bahan'!$A$2:$B$10074,2,FALSE),"") -> Acetic Acid Glasial | D76: =IFERROR(VLOOKUP(B76,'Spesifikasi Bahan'!$A$2:$C$10074,3,FALSE),"") -> CH3COOH | E76: =IFERROR(VLOOKUP(B76,'Spesifikasi Bahan'!$A$2:$E$10074,5,FALSE),"") -> 2500 | F76: =IFERROR(VLOOKUP(B76,'Spesifikasi Bahan'!$A$2:$F$10074,6,FALSE),"") -> mL | G76: =IFERROR(VLOOKUP(B76,'Spesifikasi Bahan'!$A$2:$G$10074,7,FALSE),"") -> 500 | H76: =I76-J76 -> 2230.2 | I76: =SUMIF('Form Responses Incoming'!$C$2:$C$10131,B76,'Form Responses Incoming'!$D$2:D10202) -> 2500 | J76: =SUMIF('Form Responses Usage'!$C$2:$C$11115,B76,'Form Responses Usage'!$D$2:$D$11115) -> 269.8 | K76: =IF(H76<G76,"Limited Stock","OK") -> OK | L76: =IFERROR(VLOOKUP(B76,'Spesifikasi Bahan'!$A$2:$D$10074,4,FALSE),"") -> A - 1001 - SmartLab | N76: #N/A
A77: 73 | B77: B31 | C77: =IFERROR(VLOOKUP(B77,'Spesifikasi Bahan'!$A$2:$B$10074,2,FALSE),"") -> n-Hexadecane | D77: =IFERROR(VLOOKUP(B77,'Spesifikasi Bahan'!$A$2:$C$10074,3,FALSE),"") -> C16H34 | E77: =IFERROR(VLOOKUP(B77,'Spesifikasi Bahan'!$A$2:$E$10074,5,FALSE),"") -> 250 | F77: =IFERROR(VLOOKUP(B77,'Spesifikasi Bahan'!$A$2:$F$10074,6,FALSE),"") -> mL | G77: =IFERROR(VLOOKUP(B77,'Spesifikasi Bahan'!$A$2:$G$10074,7,FALSE),"") -> 50 | H77: =I77-J77 -> 248.6 | I77: =SUMIF('Form Responses Incoming'!$C$2:$C$10131,B77,'Form Responses Incoming'!$D$2:D10203) -> 250 | J77: =SUMIF('Form Responses Usage'!$C$2:$C$11115,B77,'Form Responses Usage'!$D$2:$D$11115) -> 1.4 | K77: =IF(H77<G77,"Limited Stock","OK") -> OK | L77: =IFERROR(VLOOKUP(B77,'Spesifikasi Bahan'!$A$2:$D$10074,4,FALSE),"") -> 8.20633 - SigmaAldrich | N77: #N/A
...

Sheet Form Responses Incoming
A1: Column 1 | B1: Tanggal | C1: Kode Bahan Kimia | D1: Jumlah | E1: Satuan | F1: Expired Date
A2: 45839.551 | B2: 45839 | C2: A1 | D2: 500 | E2: Gram | F2: 46987
A3: 45840.655 | B3: 45818 | C3: A2 | D3: 500 | E3: Gram | F3: 46356
A4: 45840.696 | B4: 45819 | C4: A3 | D4: 25 | E4: Gram | F4: 46843
A5: 45840.699 | B5: 45819 | C5: A4 | D5: 250 | E5: Gram | F5: 47391
A6: 46014.709 | B6: 45819 | C6: A6 | D6: 100 | E6: Gram | F6: 47452
A7: 45840.711 | B7: 45819 | C7: A7 | D7: 25 | E7: Gram | F7: 46081
A8: 45840.712 | B8: 45819 | C8: A8 | D8: 250 | E8: Gram | F8: 46326
A9: 45840.713 | B9: 45819 | C9: A9 | D9: 500 | E9: Gram | F9: 47787
A10: 45840.713 | B10: 45819 | C10: A10 | D10: 25 | E10: Gram | F10: 46721
A11: 45840.714 | B11: 45819 | C11: A11 | D11: 50 | E11: Gram | F11: 46081
A12: 45840.716 | B12: 45819 | C12: A12 | D12: 5 | E12: Gram | F12: 46112
A13: 45840.719 | B13: 45819 | C13: A13 | D13: 10 | E13: Gram | F13: 45930
... A107: 45856.701 | B107: 45856 | C107: A65 | D107: 100 | E107: Gram | F107: 46660
A108: 45856.702 | B108: 45856 | C108: A66 | E108: Gram | F108: 46873
A109: 45861.572 | B109: 45861 | C109: A63 | D109: 100 | E109: Gram | F109: 46625
A110: 45861.572 | B110: 45861 | C110: A66 | D110: 500 | E110: Gram | F110: 46599
A111: 45861.573 | B111: 45861 | C111: A67 | D111: 100 | E111: Gram | F111: 46752
A112: 45861.573 | B112: 45861 | C112: A68 | D112: 50 | E112: Gram | F112: 46625
A113: 45863.41 | B113: 45818 | C113: A54 | D113: 250 | E113: Gram | F113: 47362
A114: 45863.411 | B114: 45819 | C114: B40 | D114: 500 | E114: mL | F114: 46507
A115: 45863.442 | B115: 45862 | C115: A69 | D115: 500 | E115: Gram | F115: 46538
A116: 45868.374 | B116: 45866 | C116: A72 | D116: 100 | E116: Gram | F116: 45505
A117: 45868.374 | B117: 45866 | C117: A13 | D117: 100 | E117: Gram | F117: 46784
A118: 45868.375 | B118: 45866 | C118: A14 | D118: 100 | E118: Gram | F118: 47422
A119: 45868.376 | B119: 45866 | C119: A11 | D119: 250 | E119: Gram | F119: 47177
A120: 45868.377 | B120: 45866 | C120: A10 | D120: 500 | E120: Gram | F120: 47453
... A214: 46108.582 | B214: 46108 | C214: B20 | D214: 250 | E214: mL | F214: 46446

Sheet Form Responses Usage
A1: Timestamp | B1: Tanggal | C1: Kode Bahan Kimia | D1: Jumlah | E1: Satuan | F1: Personil/Analis
A2: 45840.41 | B2: 45831 | C2: A24 | D2: 6 | E2: Gram | F2: Lucy
A3: 45840.411 | B3: 45831 | C3: A32 | D3: 0.25 | E3: Gram | F3: Lucy
A4: 45840.412 | B4: 45831 | C4: A34 | D4: 10 | E4: Gram | F4: Lucy
A5: 45840.413 | B5: 45831 | C5: A22 | D5: 0.5 | E5: Gram | F5: Lucy
A6: 45840.413 | B6: 45831 | C6: B33 | D6: 10 | E6: mL | F6: Lucy
A7: 45840.414 | B7: 45832 | C7: A34 | D7: 10 | E7: Gram | F7: Lucy
A8: 45840.415 | B8: 45832 | C8: A22 | D8: 0.5 | E8: Gram | F8: Lucy
A9: 45840.415 | B9: 45832 | C9: B33 | D9: 10 | E9: mL | F9: Lucy
A10: 45840.416 | B10: 45831 | C10: B35 | D10: 50 | E10: mL | F10: Lucy
A11: 45840.417 | B11: 45833 | C11: B25 | D11: 50 | E11: mL | F11: Lucy
A12: 45840.418 | B12: 45833 | C12: A34 | D12: 10 | E12: Gram | F12: Lucy
A13: 45840.419 | B13: 45833 | C13: A22 | D13: 0.5 | E13: Gram | F13: Lucy
... A975: 46052.717 | B975: 46052 | C975: A22 | D975: 2.5 | E975: Gram | F975: fajar
A976: 46052.717 | B976: 46052 | C976: A69 | D976: fajar | E976: Gram | F976: fajar
A977: 46052.717 | B977: 46052 | C977: B25 | D977: 35 | E977: mL | F977: fajar
A978: 46052.724 | B978: 46052 | C978: A96 | D978: 5.2 | E978: Gram | F978: AA
A979: 46052.724 | B979: 46052 | C979: A22 | D979: 0.3 | E979: Gram | F979: AA
A980: 46052.724 | B980: 46052 | C980: A9 | D980: 20 | E980: Gram | F980: AA
A981: 46052.725 | B981: 46052 | C981: A21 | D981: 66 | E981: Gram | F981: AA
A982: 46052.725 | B982: 46052 | C982: A52 | D982: 27.5 | E982: Gram | F982: AA
A983: 46052.726 | B983: 46052 | C983: B40 | D983: 2.5 | E983: mL | F983: AA
A984: 46052.726 | B984: 46052 | C984: B23 | D984: 50 | E984: mL | F984: AA
A985: 46052.726 | B985: 46052 | C985: B24 | D985: 100 | E985: mL | F985: AA
A986: 46055.665 | B986: 46055 | C986: A85 | D986: 2 | E986: Pcs | F986: DA
A987: 46055.666 | B987: 46055 | C987: A86 | D987: 2 | E987: Pcs | F987: DA
A988: 46055.709 | B988: 46055 | C988: A5 | D988: 15.0025 | E988: Gram | F988: Luthfi
... A1161: 46113.347 | B1161: 46112 | C1161: A70 | D1161: 8.005 | E1161: Gram | F1161: DA

Sheet Kode Barang
A1: Jenis Barang | B1: Kode Barang
A2: Padatan | B2: A
A3: Cairan | B3: B
A4: Gas | B4: C
